#!/usr/bin/env python3
import os
import sys
import django

# Add the project directory to Python path
sys.path.insert(0, os.path.dirname(os.path.dirname(os.path.abspath(__file__))))

os.environ.setdefault('DJANGO_SETTINGS_MODULE', 'sushi_core.settings')
django.setup()

from mesero.models import Orden, Mesa
from accounts.models import Usuario
from django.utils import timezone

def test_orden_creation():
    """Test Orden creation with correct field names"""
    print("üß™ TESTING ORDEN CREATION...")
    print("=" * 50)
    
    try:
        # Test 1: Check Orden model fields
        print("1. Checking Orden model fields")
        orden_fields = [f.name for f in Orden._meta.fields]
        print(f"   Available fields: {orden_fields}")
        
        if 'observaciones' in orden_fields:
            print("   ‚úÖ Field 'observaciones' exists")
        else:
            print("   ‚ùå Field 'observaciones' not found")
            
        if 'notas_cocina' in orden_fields:
            print("   ‚úÖ Field 'notas_cocina' exists")
        else:
            print("   ‚ùå Field 'notas_cocina' not found")
            
        if 'notas' in orden_fields:
            print("   ‚ùå Field 'notas' exists (should not)")
        else:
            print("   ‚úÖ Field 'notas' does not exist (correct)")
        
        # Test 2: Try creating an Orden with observaciones
        print("\n2. Testing Orden creation with observaciones")
        mesa = Mesa.objects.filter(activa=True).first()
        usuario = Usuario.objects.first()
        
        if mesa and usuario:
            # Test the creation that should work now
            orden_test = Orden(
                mesa=mesa,
                mesero=usuario,
                estado='pendiente',
                observaciones='Test notes'  # This should work
            )
            print("   ‚úÖ Orden object created successfully with observaciones")
            
            # Test the old way that was causing the error
            try:
                orden_test_bad = Orden(
                    mesa=mesa,
                    mesero=usuario,
                    estado='pendiente',
                    notas='Test notes'  # This should fail
                )
                print("   ‚ùå ERROR: Orden created with 'notas' field (should have failed)")
            except TypeError as e:
                print(f"   ‚úÖ Expected error with 'notas' field: {e}")
        else:
            print("   ‚ö†Ô∏è  No mesa or usuario found for testing")
        
        print("\n" + "=" * 50)
        print("üéâ ORDEN FIELD VALIDATION COMPLETED!")
        
    except Exception as e:
        print(f"‚ùå Error testing orden creation: {e}")
        import traceback
        traceback.print_exc()

if __name__ == '__main__':
    test_orden_creation()
